Workbook

Sheet monthly_elctricity
C2: صفحة حساب كهرباء السلم ومياه العمارة
D3: إجمالى المصروفات | K3: إجمالى المصروفات
D4: =SUM(D6:D2001) -> 9314 | K4: =SUM(K6:K2001) -> 6291.5
A5: م | B5: شهر | C5: بتاريخ | D5: تم استلام مبلغ | E5: البيان | J5: بتاريخ | K5: تم استلام مبلغ | L5: البيان
A6: 1 | B6: 1 | C6: 44939 | D6: 223 | E6: تحت حساب فاتورة الكهرباء عن شهر يناير / 2023 | J6: 44947 | K6: 662 | L6: تحت حساب فاتورة المياه عن شهر يناير /2023
A7: 2 | B7: 2 | C7: 44970 | D7: 613 | E7: تحت حساب فاتورة الكهرباء عن شهر فبراير /2023 | J7: 44985 | K7: 662 | L7: تحت حساب فاتورة المياه عن شهر فبراير /2023
A8: 3 | B8: 3 | C8: 44998 | D8: 919 | E8: تحت حساب فاتورة الكهرباء عن شهر مارس /2023
A9: 4 | B9: 4 | C9: 45029 | D9: 941 | E9: تحت حساب فاتورة الكهرباء عن شهر ابريل /2023 | J9: 45026 | K9: 1324 | L9: تحت حساب فاتورة المياه عن شهرى مارس وابريل /2023
A10: 5 | B10: 5 | C10: 45061 | D10: 687 | E10: تحت حساب فاتورة الكهرباء عن شهر مايو /2023 | J10: 45068 | K10: 277.5 | L10: تحت حساب فاتورة المياه عن شهر مايو /2023
A11: 6 | B11: 6 | C11: 45092 | D11: 543 | E11: تحت حساب فاتورة الكهرباء عن شهر يونية /2023 | J11: 45082 | K11: 551 | L11: تحت حساب فاتورة المياه عن شهر يونية /2023
A12: 7 | B12: 7 | C12: 45122 | D12: 889 | E12: تحت حساب فاتورة الكهرباء عن شهر يولية /2023
A13: 8 | B13: 8 | C13: 45158 | D13: 860 | E13: تحت حساب فاتورة الكهرباء عن شهر اغسطس /2023
A14: 9 | B14: 9 | C14: 45184 | D14: 910 | E14: تحت حساب فاتورة الكهرباء عن شهر سبتمبر /2023
A15: 10 | B15: 10 | C15: 45224 | D15: 1023 | E15: تحت حساب فاتورة الكهرباء عن شهر اكتوبر /2023
A16: 11 | B16: 11 | C16: 45245 | D16: 1022 | E16: تحت حساب فاتورة الكهرباء عن شهر نوفمبر /2023 | J16: 45249 | K16: 2345 | L16: تحت حساب فاتورة المياه عن شهور 7،8،9،10،11 /2023
A17: 12 | B17: 12 | C17: 45275 | D17: 684 | E17: تحت حساب فاتورة الكهرباء عن شهر ديسمبر /2023 | J17: 45281 | K17: 470 | L17: تحت حساب فاتورة المياه عن شهر 12/2023

Sheet payments01
C2: اصلاح وتغيير ماسورة الصرف 4متر الوسطى عند المدخل الرئيسى للعمارة
F3: عملية رقم (1) لسنة 2026 اصلاح وتغيير ماسورة الصرف 4متر الوسطى عند المدخل الرئيسى للعمارة
A4: م | B4: شقة رقم | C4: إجمالى المدفوعات | D4: إجمالى المطلوب | E4: الباقى | F4: تاريخ | G4: بيان | J4: معلومات
A5: 1 | B5: 1 | C5: 0 | D5: 0 | E5: =D5-C5 -> 0 | F5: 46101 | G5: آمال
A6: 2 | B6: 2 | C6: 0 | D6: 0 | E6: =D6-C6 -> 0 | F6: 46098 | G6: سلمى
A7: 3 | B7: 3 | C7: 0 | D7: 0 | E7: =D7-C7 -> 0 | F7: 46115 | G7: م/نادية
A8: 4 | B8: 4 | C8: 0 | D8: 0 | E8: =D8-C8 -> 0 | F8: 46098 | G8: د/عمرو
A9: 5 | B9: 5 | C9: 0 | D9: 0 | E9: =D9-C9 -> 0 | F9: 46098 | G9: ا/مكى
A10: 6 | B10: 6 | C10: 0 | D10: 0 | E10: =D10-C10 -> 0 | F10: 46098 | G10: الحاج/حسين
A11: 7 | B11: 7 | C11: 0 | D11: 0 | E11: =D11-C11 -> 0 | G11: وائل
A12: 8 | B12: 8 | C12: 0 | D12: 0 | E12: =D12-C12 -> 0 | F12: 46098 | G12: ا/مصطفى
A13: 9 | B13: 9 | C13: 0 | D13: 0 | E13: =D13-C13 -> 0 | F13: 46098 | G13: سعد عنان
A14: 10 | B14: 10 | C14: 0 | D14: 0 | E14: =D14-C14 -> 0 | F14: 46098 | G14: الحاج/حسين
A15: 11 | B15: 11 | C15: 0 | D15: 0 | E15: =D15-C15 -> 0 | F15: 46098 | G15: ايمان
A16: 12 | B16: 12 | C16: 0 | D16: 0 | E16: =D16-C16 -> 0 | F16: 46098 | G16: ا/عبد المجيد
A17: 13 | B17: 13 | C17: 0 | D17: 0 | E17: =D17-C17 -> 0 | F17: 46098 | G17: منال مصطفى
A18: 14 | B18: 14 | C18: 0 | D18: 0 | E18: =D18-C18 -> 0 | F18: 46098 | G18: منال مصطفى

Sheet payments02
C2: عملية اصلاح وتغيير 3 متر ماسورة المياه العذبة التى ضربت 30/8/2024
F3: عملية رقم (2) اصلاح وتغيير ماسورة المياه العذبة فى المدخل الرئيسى
A4: م | B4: شقة رقم | C4: إجمالى المدفوعات | D4: إجمالى المطلوب | E4: الباقى | F4: تاريخ | G4: بيان
A5: 1 | B5: 1 | E5: =D5-C5 -> 0 | G5: م/آمال
A6: 2 | B6: 2 | E6: =D6-C6 -> 0 | G6: سلمى
A7: 3 | B7: 3 | E7: =D7-C7 -> 0 | G7: م/نادية
A8: 4 | B8: 4 | E8: =D8-C8 -> 0 | G8: د/عمرو
A9: 5 | B9: 5 | E9: =D9-C9 -> 0 | G9: ا/مكى
A10: 6 | B10: 6 | E10: =D10-C10 -> 0 | G10: الحاج/حسين
A11: 7 | B11: 7 | E11: =D11-C11 -> 0 | G11: وائل
A12: 8 | B12: 8 | E12: =D12-C12 -> 0 | G12: ا/مصطفى
A13: 9 | B13: 9 | E13: =D13-C13 -> 0 | G13: سعد عنان
A14: 10 | B14: 10 | E14: =D14-C14 -> 0 | G14: الحاج/حسين
A15: 11 | B15: 11 | E15: =D15-C15 -> 0 | G15: ايمان
A16: 12 | B16: 12 | E16: =D16-C16 -> 0 | G16: ا/عبد المجيد
... A18: 14 | B18: 14 | E18: =D18-C18 -> 0 | G18: منال مصطفى

Sheet electricity
B2: صفحة قراءة عداد الكهرباء
A4: م | B4: تاريخ | C4: اليوم | D4: قراءة العداد | E4: قراءة تبليغ يوم 20 لشهر | F4: اسباب ارتفاع الاستهلاك | G4: معدل استهلاك من قراءة لاخرى | H4: أول قراءة لعداد الكهرباء | I4: آخر قراءة لعداد الكهرباء | J4: الإستهلاك من الكهرباء | K4: معدل استهلاك الكهرباء كيلووات/يوم | L4: مبلغ الفاتوة حسب الشرائح | M4: مبلغ | AB4: نهاية الشريحة | AC4: رقم الشريحة | AD4: قيمة الشريحة | AE4: خدمة عملاء
A5: 1 | B5: 43837 | D5: 21336 | H5: =LOOKUP(21340,D5:D2000,D5:D2000) -> 21336 | I5: =LOOKUP(999999,D5:D2000,D5:D2000) -> 26923 | J5: =I5-H5 -> 5587 | K5: =J5/(MAX(B4:B1999) - MIN(B4:B1999)) -> 16.241279 | AB5: 50 | AC5: 1 | AD5: 0.3 | AE5: 1
A6: 2 | B6: 43838 | D6: 21362 | G6: =(D6-D5)/(B6-B5) -> 26 | AB6: 100 | AC6: 2 | AD6: 0.4 | AE6: 2
A7: 3 | B7: 43845 | D7: 21604 | G7: =(D7-D6)/(B7-B6) -> 34.571429 | AB7: 200 | AC7: 3 | AD7: 0.5 | AE7: 6 | AF7: موحد
A8: 4 | B8: 43850 | D8: 21801 | E8: 1 | G8: =(D8-D7)/(B8-B7) -> 39.4 | AB8: 350 | AC8: 4 | AD8: 0.82 | AE8: 11
A9: 5 | B9: 43853 | D9: 21890 | G9: =(D9-D8)/(B9-B8) -> 29.666667 | AB9: 650 | AC9: 5 | AD9: 1 | AE9: 15
A10: 6 | B10: 43856 | D10: 21971 | G10: =(D10-D9)/(B10-B9) -> 27 | AB10: 1000 | AC10: 6 | AD10: 1.4 | AE10: 25
A11: 7 | B11: 43858 | D11: 22037 | G11: =(D11-D10)/(B11-B10) -> 33 | AB11: 50000 | AC11: 7 | AD11: 1.45 | AE11: 40 | AF11: موحد
A12: 8 | B12: 43860 | D12: 22092 | G12: =(D12-D11)/(B12-B11) -> 27.5
A13: 9 | B13: 43864 | D13: 22192 | G13: =(D13-D12)/(B13-B12) -> 25
A14: 10 | B14: 43866 | C14: الخميس | D14: 22252 | G14: =(D14-D13)/(B14-B13) -> 30
A15: 11 | B15: 43867 | C15: الجمعة | D15: 22292 | G15: =(D15-D14)/(B15-B14) -> 40
A16: 12 | B16: 43872 | C16: الاربعاء | D16: 22420 | G16: =(D16-D15)/(B16-B15) -> 25.6
A17: 13 | B17: 43875 | C17: السبت | D17: 22495 | G17: =(D17-D16)/(B17-B16) -> 25
A18: 14 | B18: 43876 | C18: الاحد | D18: 22522 | G18: =(D18-D17)/(B18-B17) -> 27
A19: 15 | B19: 43878 | C19: الثلاثاء | D19: 22559 | G19: =(D19-D18)/(B19-B18) -> 18.5
A20: 16 | B20: 43879 | C20: الأربعاء | D20: 22577 | G20: =(D20-D19)/(B20-B19) -> 18
A21: 17 | B21: 43880 | C21: الخميس | D21: 22597 | G21: =(D21-D20)/(B21-B20) -> 20
A22: 18 | B22: 43881 | C22: الجمعة | D22: 22618 | E22: 2 | G22: =(D22-D21)/(B22-B21) -> 21
A23: 19 | B23: 43883 | C23: الاحد | D23: 22654 | G23: =(D23-D22)/(B23-B22) -> 18
A24: 20 | B24: 43885 | C24: الإثنين | D24: 22681 | G24: =(D24-D23)/(B24-B23) -> 13.5
A25: 21 | B25: 43886 | C25: الثلاثاء | D25: 22721 | F25: ماسورة مياة مضروبة عند الجامعة والموتور يعمل على الفاضى | G25: =(D25-D24)/(B25-B24) -> 40
A26: 22 | B26: 43887 | C26: الاربعاء | D26: 22735 | G26: =(D26-D25)/(B26-B25) -> 14
A27: 23 | B27: 43890 | C27: السبت | D27: 22812 | G27: =(D27-D26)/(B27-B26) -> 25.666667
A28: 24 | B28: 43892 | C28: الاثنين | D28: 22862 | G28: =(D28-D27)/(B28-B27) -> 25
A29: 25 | B29: 43893 | C29: الثلاثاء | D29: 22883 | G29: =(D29-D28)/(B29-B28) -> 21
A30: 26 | B30: 43895 | C30: الخميس | D30: 22929 | G30: =(D30-D29)/(B30-B29) -> 23
A31: 27 | B31: 43897 | C31: السبت | D31: 22981 | G31: =(D31-D30)/(B31-B30) -> 26
A32: 28 | B32: 43899 | C32: الاثنين | D32: 23029 | G32: =(D32-D31)/(B32-B31) -> 24
A33: 29 | B33: 43900 | C33: الثلاثاء | D33: 23049 | G33: =(D33-D32)/(B33-B32) -> 20
A34: 30 | B34: 43901 | C34: الأربعاء | D34: 23072 | G34: =(D34-D33)/(B34-B33) -> 23
A35: 31 | B35: 43903 | C35: الجمعة | D35: 23121 | G35: =(D35-D34)/(B35-B34) -> 24.5
A36: 32 | B36: 43905 | C36: الاجد | D36: 23181 | G36: =(D36-D35)/(B36-B35) -> 30
A37: 33 | B37: 43908 | C37: الاربعاء | D37: 23250 | G37: =(D37-D36)/(B37-B36) -> 23
A38: 24 | B38: 43909 | C38: الخميس | D38: 23284 | G38: =(D38-D37)/(B38-B37) -> 34 | H38: بداية استخدام البالونة كالبيدا 24 لتر واستخدام نظام المفاتيح الكهربائية الاربعة للتحكم فى تشغيل الموتور واغلاقه
A39: 25 | B39: 43910 | C39: الجمعة | D39: 23302 | G39: =(D39-D38)/(B39-B38) -> 18
A40: 26 | B40: 43911 | C40: السبت | D40: 23318 | G40: =(D40-D39)/(B40-B39) -> 16
A41: 27 | B41: 43912 | C41: الأحد | D41: 23335 | G41: =(D41-D40)/(B41-B40) -> 17
A42: 28 | B42: 43913 | C42: الإثنين | D42: 23352 | G42: =(D42-D41)/(B42-B41) -> 17
...

Sheet Monthly_payments
C1: متحصلات شهور سنة 2023 لكل شقة
B5: شهر | C5: شقة 1 | D5: شقة 2 | E5: شقة 3 | F5: شقة 4 | G5: شقة 5 | H5: شقة 6 | I5: شقة 7 | J5: شقة 8 | K5: شقة 9 | L5: شقة 10 | M5: شقة 11 | N5: شقة 12 | O5: شقة 13 | P5: شقة 14
B6: 1 | C6: =Apartment1!D6 -> 150 | D6: =Apartment2!D6 -> 75 | E6: =Apartment3!D6 -> 150 | F6: =Apartment4!D6 -> 150 | G6: =Apartment5!D6 -> 300 | H6: =Apartment6!D6 -> 300 | I6: =Apartment7!D6 -> 300 | J6: =Apartment8!D6 -> 300 | K6: =Apartment9!D6 -> 150 | L6: =Apartment10!D6 -> 150 | M6: =Apartment11!D6 -> 150 | N6: =Apartment12!D6 -> 250 | O6: =Apartment13!D6 -> 125 | P6: =Apartment14!D6 -> 125
B7: 2 | C7: =Apartment1!D7 -> 150 | D7: =Apartment2!D7 -> 75 | E7: =Apartment3!D7 -> 150 | F7: =Apartment4!D7 -> 150 | G7: =Apartment5!D7 -> 300 | H7: =Apartment6!D7 -> 300 | I7: =Apartment7!D7 -> 300 | J7: =Apartment8!D7 -> 300 | K7: =Apartment9!D7 -> 150 | L7: =Apartment10!D7 -> 150 | M7: =Apartment11!D7 -> 150 | N7: =Apartment12!D7 -> 250 | O7: =Apartment13!D7 -> 125 | P7: =Apartment14!D7 -> 125
B8: 3 | C8: =Apartment1!D8 -> 150 | D8: =Apartment2!D8 -> 75 | E8: =Apartment3!D8 -> 150 | F8: =Apartment4!D8 -> 150 | G8: =Apartment5!D8 -> 300 | H8: =Apartment6!D8 -> 300 | I8: =Apartment7!D8 -> 300 | J8: =Apartment8!D8 -> 300 | K8: =Apartment9!D8 -> 150 | L8: =Apartment10!D8 -> 150 | M8: =Apartment11!D8 -> 150 | N8: =Apartment12!D8 -> 250 | O8: =Apartment13!D8 -> 125 | P8: =Apartment14!D8 -> 125
B9: 4 | C9: =Apartment1!D9 -> 150 | D9: =Apartment2!D9 -> 75 | E9: =Apartment3!D9 -> 150 | F9: =Apartment4!D9 -> 150 | G9: =Apartment5!D9 -> 300 | H9: =Apartment6!D9 -> 300 | I9: =Apartment7!D9 -> 300 | J9: =Apartment8!D9 -> 300 | K9: =Apartment9!D9 -> 150 | L9: =Apartment10!D9 -> 150 | M9: =Apartment11!D9 -> 150 | N9: =Apartment12!D9 -> 250 | O9: =Apartment13!D9 -> 150 | P9: =Apartment14!D9 -> 150
B10: 5 | C10: =Apartment1!D10 -> 150 | D10: =Apartment2!D10 -> 75 | E10: =Apartment3!D10 -> 150 | F10: =Apartment4!D10 -> 150 | G10: =Apartment5!D10 -> 300 | H10: =Apartment6!D10 -> 300 | I10: =Apartment7!D10 -> 300 | J10: =Apartment8!D10 -> 300 | K10: =Apartment9!D10 -> 150 | L10: =Apartment10!D10 -> 150 | M10: =Apartment11!D10 -> 150 | N10: =Apartment12!D10 -> 250 | O10: =Apartment13!D10 -> 150 | P10: =Apartment14!D10 -> 150
B11: 6 | C11: =Apartment1!D11 -> 150 | D11: =Apartment2!D11 -> 150 | E11: =Apartment3!D11 -> 150 | F11: =Apartment4!D11 -> 150 | G11: =Apartment5!D11 -> 0 | H11: =Apartment6!D11 -> 300 | I11: =Apartment7!D11 -> 300 | J11: =Apartment8!D11 -> 300 | K11: =Apartment9!D11 -> 150 | L11: =Apartment10!D11 -> 150 | M11: =Apartment11!D11 -> 150 | N11: =Apartment12!D11 -> 250 | O11: =Apartment13!D11 -> 0 | P11: =Apartment14!D11 -> 0
B12: 7 | C12: =Apartment1!D12 -> 150 | D12: =Apartment2!D12 -> 150 | E12: =Apartment3!D12 -> 150 | F12: =Apartment4!D12 -> 150 | G12: =Apartment5!D12 -> 0 | H12: =Apartment6!D12 -> 300 | I12: =Apartment7!D12 -> 300 | J12: =Apartment8!D12 -> 300 | K12: =Apartment9!D12 -> 150 | L12: =Apartment10!D12 -> 150 | M12: =Apartment11!D12 -> 150 | N12: =Apartment12!D12 -> 250 | O12: =Apartment13!D12 -> 0 | P12: =Apartment14!D12 -> 0
B13: 8 | C13: =Apartment1!D13 -> 0 | D13: =Apartment2!D13 -> 150 | E13: =Apartment3!D13 -> 150 | F13: =Apartment4!D13 -> 150 | G13: =Apartment5!D13 -> 0 | H13: =Apartment6!D13 -> 300 | I13: =Apartment7!D13 -> 300 | J13: =Apartment8!D13 -> 300 | K13: =Apartment9!D13 -> 150 | L13: =Apartment10!D13 -> 150 | M13: =Apartment11!D13 -> 0 | N13: =Apartment12!D13 -> 250 | O13: =Apartment13!D13 -> 0 | P13: =Apartment14!D13 -> 0
B14: 9 | C14: =Apartment1!D14 -> 0 | D14: =Apartment2!D14 -> 150 | E14: =Apartment3!D14 -> 150 | F14: =Apartment4!D14 -> 150 | G14: =Apartment5!D14 -> 0 | H14: =Apartment6!D14 -> 300 | I14: =Apartment7!D14 -> 300 | J14: =Apartment8!D14 -> 300 | K14: =Apartment9!D14 -> 150 | L14: =Apartment10!D14 -> 150 | M14: =Apartment11!D14 -> 0 | N14: =Apartment12!D14 -> 0 | O14: =Apartment13!D14 -> 0 | P14: =Apartment14!D14 -> 0
B15: 10 | C15: =Apartment1!D15 -> 0 | D15: =Apartment2!D15 -> 150 | E15: =Apartment3!D15 -> 0 | F15: =Apartment4!D15 -> 0 | G15: =Apartment5!D15 -> 0 | H15: =Apartment6!D15 -> 300 | I15: =Apartment7!D15 -> 0 | J15: =Apartment8!D15 -> 0 | K15: =Apartment9!D15 -> 0 | L15: =Apartment10!D15 -> 150 | M15: =Apartment11!D15 -> 0 | N15: =Apartment12!D15 -> 0 | O15: =Apartment13!D15 -> 0 | P15: =Apartment14!D15 -> 0
B16: 11 | C16: =Apartment1!D16 -> 0 | D16: =Apartment2!D16 -> 150 | E16: =Apartment3!D16 -> 0 | F16: =Apartment4!D16 -> 0 | G16: =Apartment5!D16 -> 0 | H16: =Apartment6!D16 -> 300 | I16: =Apartment7!D16 -> 0 | J16: =Apartment8!D16 -> 0 | K16: =Apartment9!D16 -> 0 | L16: =Apartment10!D16 -> 150 | M16: =Apartment11!D16 -> 0 | N16: =Apartment12!D16 -> 0 | O16: =Apartment13!D16 -> 0 | P16: =Apartment14!D16 -> 0
B17: 12 | C17: =Apartment1!D17 -> 0 | D17: =Apartment2!D17 -> 150 | E17: =Apartment3!D17 -> 0 | F17: =Apartment4!D17 -> 0 | G17: =Apartment5!D17 -> 0 | H17: =Apartment6!D17 -> 300 | I17: =Apartment7!D17 -> 0 | J17: =Apartment8!D17 -> 0 | K17: =Apartment9!D17 -> 0 | L17: =Apartment10!D17 -> 150 | M17: =Apartment11!D17 -> 0 | N17: =Apartment12!D17 -> 0 | O17: =Apartment13!D17 -> 0 | P17: =Apartment14!D17 -> 0

Sheet payments
C2: متابعة مدفوعات كل شقة فيما يخص مبلغ الصيانة الشهرية فقط
G3: صيانات فجائية (طارئة)
A4: م | B4: شقة رقم | C4: إجمالى المدفوعات | D4: إجمالى المطلوب | E4: الباقى | F4: المالك | G4: إجمالى المدفوعات | H4: إجمالى المطلوب | I4: الباقى
A5: 1 | B5: 1 | C5: =Apartment1!D4 -> 1050 | E5: =D5-C5 -> -1050 | F5: عمرو نبيل | I5: =H5-G5 -> 0
A6: 2 | B6: 2 | C6: =Apartment2!D4 -> 1425 | E6: =D6-C6 -> -1425 | F6: عزة عنان | I6: =H6-G6 -> 0
A7: 3 | B7: 3 | C7: =Apartment3!D4 -> 1350 | E7: =D7-C7 -> -1350 | F7: وائل محمد على | I7: =H7-G7 -> 0
A8: 4 | B8: 4 | C8: =Apartment4!D4 -> 1350 | E8: =D8-C8 -> -1350 | F8: وائل محمد على | I8: =H8-G8 -> 0
A9: 5 | B9: 5 | C9: =Apartment5!D4 -> 1500 | E9: =D9-C9 -> -1500 | F9: الحاج / مكى | I9: =H9-G9 -> 0
A10: 6 | B10: 6 | C10: 0 | E10: =D10-C10 -> 0 | F10: الحاج / حسين عثمان | I10: =H10-G10 -> 0
A11: 7 | B11: 7 | C11: =Apartment7!D4 -> 2700 | E11: =D11-C11 -> -2700 | F11: وائل محمد على | I11: =H11-G11 -> 0
A12: 8 | B12: 8 | C12: =Apartment8!D4 -> 2700 | E12: =D12-C12 -> -2700 | F12: ا.مصطفى | I12: =H12-G12 -> 0
A13: 9 | B13: 9 | C13: =Apartment9!D4 -> 1350 | E13: =D13-C13 -> -1350 | F13: م/ سعد عنان | I13: =H13-G13 -> 0
A14: 10 | B14: 10 | E14: =D14-C14 -> 0 | F14: الحاج / حسين عثمان | I14: =H14-G14 -> 0
A15: 11 | B15: 11 | C15: =Apartment11!D4 -> 1050 | E15: =D15-C15 -> -1050 | F15: ايمان محمد على | I15: =H15-G15 -> 0
A16: 12 | B16: 12 | C16: 0 | E16: =D16-C16 -> 0 | F16: أ/ عبد المجيد | I16: =H16-G16 -> 0
A17: 13 | B17: 13 | C17: =Apartment13!D4 -> 675 | E17: =D17-C17 -> -675 | F17: ا/ محمد التعلب | I17: =H17-G17 -> 0
A18: 14 | B18: 14 | C18: =Apartment14!D4 -> 675 | E18: =D18-C18 -> -675 | F18: عمروالتعلب | I18: =H18-G18 -> 0

Sheet Apartment14
C2: صفحة شقة رقم 14 - عمرو تعلب
D3: إجمالى الايرادات | F3: إجمالى المبلغ المطلوب
D4: =SUM(D6:D2001) -> 675 | F4: =SUM(F6:F2001) -> 1725
A5: م | B5: شهر | C5: بتاريخ | D5: تم استلام مبلغ | E5: البيان | F5: مطلوب مبلغ | G5: البيان
A6: 1 | B6: 1 | C6: 46134 | D6: 125 | F6: 125 | G6: عن صيانة شهر يناير/2026
A7: 2 | B7: 2 | C7: 46134 | D7: 125 | F7: 125 | G7: تحت حساب الصيانة لشهر فبراير
A8: 3 | B8: 3 | C8: 46242 | D8: 125 | F8: 125 | G8: تحت حساب صيانة شهر 3
A9: 4 | B9: 4 | C9: 46159 | D9: 150 | F9: 150 | G9: تحت حساب صيانة شهر 4
A10: 5 | B10: 5 | C10: 46159 | D10: 150 | F10: 150 | G10: تحت حساب صيانة شهر 5
A11: 6 | B11: 6 | C11: 46242 | F11: 150 | G11: تحت حساب صيانة شهر 6
A12: 7 | B12: 7 | C12: 46242 | F12: 150 | G12: تحت حساب صيانة شهر 7
A13: 8 | B13: 8 | C13: 46371 | F13: 150 | G13: تحت حساب صيانة شهر 8
A14: 9 | B14: 9 | C14: 46371 | F14: 150 | G14: تحت حساب صيانة شهر 9
A15: 10 | B15: 10 | C15: 46371 | F15: 150 | G15: تحت حساب صيانة شهر 10
A16: 11 | B16: 11 | C16: 46371 | F16: 150 | G16: تحت حساب صيانة شهر 11
A17: 12 | B17: 12 | C17: 46371 | F17: 150 | G17: تحت حساب صيانة شهر 12

Sheet Apartment12
C2: صفحة شقة رقم 12 - عبد المجيد
D3: إجمالى الايرادات | F3: إجمالى المبلغ المطلوب
D4: =SUM(D6:D2001) -> 2000 | F4: =SUM(F6:F2001) -> 3000
A5: م | B5: شهر | C5: بتاريخ | D5: تم استلام مبلغ | E5: البيان | F5: مطلوب مبلغ | G5: البيان
A6: 1 | B6: 1 | C6: 46026 | D6: 250 | F6: 250 | G6: تحت حساب صيانة شهر 1/ 2026
A7: 2 | B7: 2 | C7: 46065 | D7: 250 | F7: 250 | G7: تحت حساب صيانة شهر 2
A8: 3 | B8: 3 | C8: 46115 | D8: 250 | F8: 250 | G8: تحت حساب صيانة شهر 3
A9: 4 | B9: 4 | C9: 46152 | D9: 250 | F9: 250 | G9: تحت حساب صيانة شهر 4
A10: 5 | B10: 5 | C10: 46152 | D10: 250 | F10: 250 | G10: تحت حساب صيانة شهر 5
A11: 6 | B11: 6 | C11: 46186 | D11: 250 | F11: 250 | G11: تحت حساب صيانة شهر 6
A12: 7 | B12: 7 | C12: 46216 | D12: 250 | F12: 250 | G12: تحت حساب صيانة شهر 7
A13: 8 | B13: 8 | C13: 46252 | D13: 250 | F13: 250 | G13: تحت حساب صيانة شهر 8
A14: 9 | B14: 9 | F14: 250 | G14: تحت حساب صيانة شهر 9
A15: 10 | B15: 10 | F15: 250 | G15: تحت حساب صيانة شهر 10
A16: 11 | B16: 11 | F16: 250 | G16: تحت حساب صيانة شهر 11
A17: 12 | B17: 12 | F17: 250 | G17: تحت حساب صيانة شهر 12

Sheet Apartment13
C2: صفحة شقة رقم 13 - منال مصطفى
D3: إجمالى الايرادات | F3: إجمالى المبلغ المطلوب
D4: =SUM(D6:D2001) -> 675 | F4: =SUM(F6:F2001) -> 1725
A5: م | B5: شهر | C5: بتاريخ | D5: تم استلام مبلغ | E5: البيان | F5: مطلوب مبلغ | G5: البيان
A6: 1 | B6: 1 | C6: 46134 | D6: 125 | F6: 125 | G6: تحت حساب الصيانة لشهر يناير
A7: 2 | B7: 2 | C7: 46134 | D7: 125 | F7: 125 | G7: تحت حساب الصيانة لشهر فبراير
A8: 3 | B8: 3 | C8: 46242 | D8: 125 | F8: 125 | G8: تحت حساب صيانة شهر 3
A9: 4 | B9: 4 | C9: 46159 | D9: 150 | F9: 150 | G9: تحت حساب صيانة شهر 4
A10: 5 | B10: 5 | C10: 46159 | D10: 150 | F10: 150 | G10: تحت حساب صيانة شهر 5
A11: 6 | B11: 6 | C11: 46242 | F11: 150 | G11: تحت حساب صيانة شهر 6
A12: 7 | B12: 7 | C12: 46242 | F12: 150 | G12: تحت حساب صيانة شهر 7
A13: 8 | B13: 8 | C13: 46371 | F13: 150 | G13: تحت حساب صيانة شهر 8
A14: 9 | B14: 9 | C14: 46371 | F14: 150 | G14: تحت حساب صيانة شهر 9
A15: 10 | B15: 10 | C15: 46371 | F15: 150 | G15: تحت حساب صيانة شهر 10
A16: 11 | B16: 11 | C16: 46371 | F16: 150 | G16: تحت حساب صيانة شهر 11
A17: 12 | B17: 12 | C17: 46371 | F17: 150 | G17: تحت حساب صيانة شهر 12
I20: حساب شقة 13 ، 14 من شهر11 حتى شهر 12
I21: لسنة 2026
G22: م | H22: شقة رقم | I22: المبلغ | J22: البيان
G24: 1
G25: 2
G26: إجمالى المطلوب | I26: =SUM(I23:I25) -> 0 | J26: جنيه | Q26: تم الدفع

Sheet Apartment11
C2: صفحة شقة رقم 11 - إيمان محمد على
D3: إجمالى الايرادات | F3: إجمالى المبلغ المطلوب
D4: =SUM(D6:D2001) -> 1050 | F4: =SUM(F6:F2001) -> 1800
A5: م | B5: شهر | C5: بتاريخ | D5: تم استلام مبلغ | E5: البيان | F5: مطلوب مبلغ | G5: البيان
A6: 1 | B6: 1 | C6: 46092 | D6: 150 | F6: 150 | G6: حساب صيانة شهر يناير /2026
A7: 2 | B7: 2 | C7: 46092 | D7: 150 | F7: 150 | G7: حساب صيانة شهر فبراير /2026
A8: 3 | B8: 3 | C8: 46092 | D8: 150 | F8: 150 | G8: تحت حساب صيانة شهر 3
A9: 4 | B9: 4 | C9: 46225 | D9: 150 | F9: 150 | G9: تحت حساب صيانة شهر 4
A10: 5 | B10: 5 | C10: 46225 | D10: 150 | F10: 150 | G10: تحت حساب صيانة شهر 5
A11: 6 | B11: 6 | C11: 46225 | D11: 150 | F11: 150 | G11: تحت حساب صيانة شهر 6
A12: 7 | B12: 7 | C12: 46225 | D12: 150 | F12: 150 | G12: تحت حساب صيانة شهر 7
A13: 8 | B13: 8 | C13: 46372 | F13: 150 | G13: تحت حساب صيانة شهر 8
A14: 9 | B14: 9 | C14: 46372 | F14: 150 | G14: تحت حساب صيانة شهر 9
A15: 10 | B15: 10 | C15: 46372 | F15: 150 | G15: تحت حساب صيانة شهر 10
A16: 11 | B16: 11 | C16: 46372 | F16: 150 | G16: تحت حساب صيانة شهر 11
A17: 12 | B17: 12 | C17: 46372 | F17: 150 | G17: تحت حساب صيانة شهر 12

Sheet Apartment10
C2: صفحة شقة رقم 10 - الحاج/حسين
D3: إجمالى الايرادات | F3: إجمالى المبلغ المطلوب
D4: =SUM(D6:D2001) -> 1800 | F4: =SUM(F6:F2001) -> 1800
A5: م | B5: شهر | C5: بتاريخ | D5: تم استلام مبلغ | E5: البيان | F5: مطلوب مبلغ | G5: البيان
A6: 1 | B6: 1 | C6: 45318 | D6: 150 | F6: 150 | G6: تحت حساب صيانة شهر 1/ 2026
A7: 2 | B7: 2 | C7: 45318 | D7: 150 | F7: 150 | G7: تحت حساب صيانة شهر 2
A8: 3 | B8: 3 | C8: 45318 | D8: 150 | F8: 150 | G8: تحت حساب صيانة شهر 3
A9: 4 | B9: 4 | C9: 45318 | D9: 150 | F9: 150 | G9: تحت حساب صيانة شهر 4
A10: 5 | B10: 5 | C10: 45318 | D10: 150 | F10: 150 | G10: تحت حساب صيانة شهر 5
A11: 6 | B11: 6 | C11: 45318 | D11: 150 | F11: 150 | G11: تحت حساب صيانة شهر 6
A12: 7 | B12: 7 | C12: 45569 | D12: 150 | F12: 150 | G12: تحت حساب صيانة شهر 7
A13: 8 | B13: 8 | C13: 45569 | D13: 150 | F13: 150 | G13: تحت حساب صيانة شهر 8
A14: 9 | B14: 9 | C14: 45569 | D14: 150 | F14: 150 | G14: تحت حساب صيانة شهر 9
A15: 10 | B15: 10 | C15: 45569 | D15: 150 | F15: 150 | G15: تحت حساب صيانة شهر 10
A16: 11 | B16: 11 | C16: 45569 | D16: 150 | F16: 150 | G16: تحت حساب صيانة شهر 11
A17: 12 | B17: 12 | C17: 45569 | D17: 150 | F17: 150 | G17: تحت حساب صيانة شهر 12

Sheet Apartment9
C2: صفحة شقة رقم 9 - م/سعد عنان
D3: إجمالى الايرادات | F3: إجمالى المبلغ المطلوب | O3: حساب شقة 9 فيما يخص من شهر 1حتى شهر 12 /2020 بالاضافة الى حصة الشقة من حسابات أخرى
D4: =SUM(D6:D2004) -> 1350 | F4: =SUM(F6:F2004) -> 1800
A5: م | B5: شهر | C5: بتاريخ | D5: تم استلام مبلغ | E5: البيان | F5: مطلوب مبلغ | G5: البيان | P5: م | Q5: مبلغ | R5: بيان
A6: 1 | B6: 1 | C6: 46092 | D6: 150 | F6: 150 | G6: حساب صيانة شهر يناير | P6: 1
A7: 2 | B7: 2 | C7: 46092 | D7: 150 | F7: 150 | G7: حساب صيانة شهر فبراير | P7: 2
A8: 3 | B8: 3 | C8: 46092 | D8: 150 | F8: 150 | G8: تحت حساب صيانة شهر 3 | P8: 3
A9: 4 | B9: 4 | C9: 46158 | D9: 150 | F9: 150 | G9: تحت حساب صيانة شهر 4 | P9: 4
A10: 5 | B10: 5 | C10: 46158 | D10: 150 | F10: 150 | G10: تحت حساب صيانة شهر 5 | P10: 5
A11: 6 | B11: 6 | C11: 46158 | D11: 150 | F11: 150 | G11: تحت حساب صيانة شهر 6 | P11: 6
A12: 7 | B12: 7 | C12: 46261 | D12: 150 | F12: 150 | G12: تحت حساب صيانة شهر 7 | P12: إجمالى | Q12: =SUM(Q6:Q11) -> 0
A13: 8 | B13: 8 | C13: 46261 | D13: 150 | F13: 150 | G13: تحت حساب صيانة شهر 8
A14: 9 | B14: 9 | C14: 46261 | D14: 150 | F14: 150 | G14: تحت حساب صيانة شهر 9 | P14: المطلوب | Q14: =Q12-Q13 -> 0
A15: 10 | B15: 10 | C15: 46359 | F15: 150 | G15: تحت حساب صيانة شهر 10
A16: 11 | B16: 11 | C16: 46359 | F16: 150 | G16: تحت حساب صيانة شهر 11
A17: 12 | B17: 12 | C17: 46359 | F17: 150 | G17: تحت حساب صيانة شهر 12

Sheet Apartment8
C2: صفحة شقة رقم 8 - مصطفى
D3: إجمالى الايرادات | F3: إجمالى المبلغ المطلوب
D4: =SUM(D6:D2001) -> 2700 | F4: =SUM(F6:F2001) -> 3600
A5: م | B5: شهر | C5: بتاريخ | D5: تم استلام مبلغ | E5: البيان | F5: مطلوب مبلغ | G5: البيان
A6: 1 | B6: 1 | C6: 45315 | D6: 300 | F6: 300 | G6: تحت حساب صيانة شهر يناير /2026
A7: 2 | B7: 2 | C7: 46080 | D7: 300 | F7: 300 | G7: تحت حساب صيانة شهر فبراير /2026
A8: 3 | B8: 3 | C8: 46093 | D8: 300 | F8: 300 | G8: تحت حساب صيانة شهر مارس /2026
A9: 4 | B9: 4 | C9: 46158 | D9: 300 | F9: 300 | G9: تحت حساب صيانة شهر ابريل /2026
A10: 5 | B10: 5 | C10: 46158 | D10: 300 | F10: 300 | G10: تحت حساب صيانة شهر مايو /2026
A11: 6 | B11: 6 | C11: 46190 | D11: 300 | F11: 300 | G11: تحت حساب صيانة شهر يونية /2026
A12: 7 | B12: 7 | C12: 46270 | D12: 300 | F12: 300 | G12: تحت حساب صيانة شهر يوليو /2026
A13: 8 | B13: 8 | C13: 46270 | D13: 300 | F13: 300 | G13: تحت حساب صيانة شهر 8
A14: 9 | B14: 9 | C14: 46289 | D14: 300 | F14: 300 | G14: تحت حساب صيانة شهر 9
A15: 10 | B15: 10 | C15: 46357 | F15: 300 | G15: تحت حساب صيانة شهر 10
A16: 11 | B16: 11 | C16: 46357 | F16: 300 | G16: تحت حساب صيانة شهر نوفمبر / 2026
A17: 12 | B17: 12 | C17: 46357 | F17: 300 | G17: تحت حساب صيانة شهر ديسمبر /2026

Sheet Apartment7
C2: صفحة شقة رقم 7 - وائل محمد على
D3: إجمالى الايرادات | F3: إجمالى المبلغ المطلوب
D4: =SUM(D6:D2001) -> 2700 | F4: =SUM(F6:F2001) -> 3600
A5: م | B5: شهر | C5: بتاريخ | D5: تم استلام مبلغ | E5: البيان | F5: مطلوب مبلغ | G5: البيان
A6: 1 | B6: 1 | C6: 45314 | D6: 300 | F6: 300 | G6: تحت حساب صيانة شهر يناير / 2024
A7: 2 | B7: 2 | C7: 45322 | D7: 300 | F7: 300 | G7: تحت حساب صيانة شهر فبراير / 2024
A8: 3 | B8: 3 | C8: 46084 | D8: 300 | F8: 300 | G8: تحت حساب صيانة شهر مارس / 2024
A9: 4 | B9: 4 | C9: 45384 | D9: 300 | F9: 300 | G9: تحت حساب صيانة شهر ابريل / 2024
A10: 5 | B10: 5 | C10: 45413 | D10: 300 | F10: 300 | G10: تحت حساب صيانة شهر مايو / 2024
A11: 6 | B11: 6 | C11: 45449 | D11: 300 | F11: 300 | G11: تحت حساب صيانة شهر يونية / 2024
A12: 7 | B12: 7 | C12: 45474 | D12: 300 | F12: 300 | G12: تحت حساب صيانة شهر يولية /2024
A13: 8 | B13: 8 | C13: 46235 | D13: 300 | F13: 300 | G13: تحت حساب صيانة شهر اغسطس/2024
A14: 9 | B14: 9 | C14: 46267 | D14: 300 | F14: 300 | G14: تحت حساب صيانة شهر سبتمبر/2024
A15: 10 | B15: 10 | C15: 45567 | F15: 300 | G15: تحت حساب صيانة شهر اكتوبر/2024
A16: 11 | B16: 11 | C16: 45597 | F16: 300 | G16: تحت حساب صيانة شهر نوفمبر /2024
A17: 12 | B17: 12 | C17: 46358 | F17: 300 | G17: تحت حساب صيانة شهر ديسمبر /2024

Sheet Apartment6
C2: صفحة شقة رقم 6 - الحاج/حسين
D3: إجمالى الايرادات | F3: إجمالى المبلغ المطلوب
D4: =SUM(D6:D2001) -> 3600 | F4: =SUM(F6:F2001) -> 3600
A5: م | B5: شهر | C5: بتاريخ | D5: تم استلام مبلغ | E5: البيان | F5: مطلوب مبلغ | G5: البيان
A6: 1 | B6: 1 | C6: 46142 | D6: 300 | F6: 300 | G6: تحت حساب صيانة شهر يناير/2026
A7: 2 | B7: 2 | C7: 46142 | D7: 300 | F7: 300 | G7: تحت حساب صيانة شهر فبراير/2026
A8: 3 | B8: 3 | C8: 46142 | D8: 300 | F8: 300 | G8: تحت حساب صيانة شهر 3
A9: 4 | B9: 4 | C9: 46142 | D9: 300 | F9: 300 | G9: تحت حساب صيانة شهر 4
A10: 5 | B10: 5 | C10: 46142 | D10: 300 | F10: 300 | G10: تحت حساب صيانة شهر 5
A11: 6 | B11: 6 | C11: 46142 | D11: 300 | F11: 300 | G11: تحت حساب صيانة شهر 6
A12: 7 | B12: 7 | C12: 46142 | D12: 300 | F12: 300 | G12: تحت حساب صيانة شهر 7
A13: 8 | B13: 8 | C13: 46142 | D13: 300 | F13: 300 | G13: تحت حساب صيانة شهر 8
A14: 9 | B14: 9 | C14: 46142 | D14: 300 | F14: 300 | G14: تحت حساب صيانة شهر 9
A15: 10 | B15: 10 | C15: 46142 | D15: 300 | F15: 300 | G15: تحت حساب صيانة شهر 10
A16: 11 | B16: 11 | C16: 46142 | D16: 300 | F16: 300 | G16: تحت حساب صيانة شهر 11
A17: 12 | B17: 12 | C17: 46142 | D17: 300 | F17: 300 | G17: تحت حساب صيانة شهر 12 | K17: عام مسدد بالكامل

Sheet Apartment5
C2: صفحة شقة رقم 5 - رندة سابقا (الحاج/ ماكى)
D3: إجمالى الايرادات | F3: إجمالى المبلغ المطلوب
D4: =SUM(D6:D2001) -> 1500 | F4: =SUM(F6:F2001) -> 3600
A5: م | B5: شهر | C5: بتاريخ | D5: تم استلام مبلغ | E5: البيان | F5: مطلوب مبلغ | G5: البيان
A6: 1 | B6: 1 | C6: 46335 | D6: 300 | F6: 300 | G6: تحت حساب صيانة شهر يناير/2026
A7: 2 | C7: 46335 | D7: 300 | F7: 300 | G7: تحت حساب صيانة شهر فبراير/2026
A8: 3 | C8: 46335 | D8: 300 | F8: 300 | G8: تحت حساب صيانة شهر 3
A9: 4 | C9: 46335 | D9: 300 | F9: 300 | G9: تحت حساب صيانة شهر 4
A10: 5 | C10: 46335 | D10: 300 | F10: 300 | G10: تحت حساب صيانة شهر 5
A11: 6 | C11: 46335 | F11: 300 | G11: تحت حساب صيانة شهر 6
A12: 7 | C12: 46335 | F12: 300 | G12: تحت حساب صيانة شهر 7
A13: 8 | C13: 46335 | F13: 300 | G13: تحت حساب صيانة شهر 8
A14: 9 | C14: 46335 | F14: 300 | G14: تحت حساب صيانة شهر 9
A15: 10 | C15: 46335 | F15: 300 | G15: تحت حساب صيانة شهر 10
A16: 11 | C16: 46335 | F16: 300 | G16: تحت حساب صيانة شهر 11
A17: 12 | C17: 46335 | F17: 300 | G17: تحت حساب صيانة شهر 12

Sheet Apartment4
C2: صفحة شقة رقم 4 - وائل محمد على - م/عمرو
D3: إجمالى الايرادات | F3: إجمالى المبلغ المطلوب
D4: =SUM(D6:D2001) -> 1350 | F4: =SUM(F6:F2001) -> 1800
A5: م | B5: شهر | C5: بتاريخ | D5: تم استلام مبلغ | E5: البيان | F5: مطلوب مبلغ | G5: البيان
A6: 1 | B6: 1 | C6: 45292 | D6: 150 | F6: 150 | G6: تحت حساب صيانة شهر يناير
A7: 2 | B7: 2 | C7: 45322 | D7: 150 | F7: 150 | G7: تحت حساب صيانة شهر فبراير
A8: 3 | B8: 3 | C8: 46084 | D8: 150 | F8: 150 | G8: تحت حساب صيانة شهر مارس /2024
A9: 4 | B9: 4 | C9: 45384 | D9: 150 | F9: 150 | G9: تحت حساب صيانة شهر ابريل /2024
A10: 5 | B10: 5 | C10: 45413 | D10: 150 | F10: 150 | G10: تحت حساب صيانة شهر مايو /2024
A11: 6 | B11: 6 | C11: 45449 | D11: 150 | F11: 150 | G11: تحت حساب صيانة شهر يونية / 2024
A12: 7 | B12: 7 | C12: 45474 | D12: 150 | F12: 150 | G12: تحت حساب صيانة شهر يولية / 2024
A13: 8 | B13: 8 | C13: 46235 | D13: 150 | F13: 150 | G13: تحت حساب صيانة شهر اغسطس/ 2024
A14: 9 | B14: 9 | C14: 46267 | D14: 150 | F14: 150 | G14: تحت حساب صيانة شهر سبتمبر/ 2024
A15: 10 | B15: 10 | C15: 45567 | F15: 150 | G15: تحت حساب صيانة شهر اكتوبر /2024
A16: 11 | B16: 11 | C16: 46335 | F16: 150 | G16: تحت حساب صيانة شهر نوفمبر/ 2024
A17: 12 | B17: 12 | C17: 46358 | F17: 150 | G17: تحت حساب صيانة شهر ديسمبر/ 2024

Sheet Apartment3
C2: صفحة شقة رقم 3 - وائل محمد على (محمد ناجى)
D3: إجمالى الايرادات | F3: إجمالى المبلغ المطلوب
D4: =SUM(D6:D2001) -> 1350 | F4: =SUM(F6:F2001) -> 1800
A5: م | B5: شهر | C5: بتاريخ | D5: تم استلام مبلغ | E5: البيان | F5: مطلوب مبلغ | G5: البيان
A6: 1 | B6: 1 | C6: 45292 | D6: 150 | F6: 150 | G6: تحت حساب صيانة شهر يناير
A7: 2 | B7: 2 | C7: 45322 | D7: 150 | F7: 150 | G7: تحت حساب صيانة شهر فبراير
A8: 3 | B8: 3 | C8: 46084 | D8: 150 | F8: 150 | G8: تحت حساب صيانة شهر مارس /2024
A9: 4 | B9: 4 | C9: 45384 | D9: 150 | F9: 150 | G9: تحت حساب صيانة شهر ابريل /2024
A10: 5 | B10: 5 | C10: 45413 | D10: 150 | F10: 150 | G10: تحت حساب صيانة شهر مايو /2024
A11: 6 | B11: 6 | C11: 45449 | D11: 150 | F11: 150 | G11: تحت حساب صيانة شهر يونية/ 2024
A12: 7 | B12: 7 | C12: 45474 | D12: 150 | F12: 150 | G12: تحت حساب صيانة شهر يولية/ 2024
A13: 8 | B13: 8 | C13: 46235 | D13: 150 | F13: 150 | G13: تحت حساب صيانة شهر اغسطس/ 2024
A14: 9 | B14: 9 | C14: 46267 | D14: 150 | F14: 150 | G14: تحت حساب صيانة شهر سبتمبر/ 2024
A15: 10 | B15: 10 | C15: 46297 | F15: 150 | G15: تحت حساب صيانة شهر اكتوبر /2024
A16: 11 | B16: 11 | C16: 46335 | F16: 150 | G16: تحت حساب صيانة شهر نوفمبر/ 2024
A17: 12 | B17: 12 | C17: 46357 | F17: 150 | G17: تحت حساب صيانة شهر ديسمبر/ 2024

Sheet Apartment2
C2: صفحة شقة رقم 2 - عزة عنان
D3: إجمالى الايرادات | F3: إجمالى المبلغ المطلوب
D4: =SUM(D6:D2001) -> 1425 | F4: =SUM(F6:F2001) -> 1425
A5: م | B5: شهر | C5: بتاريخ | D5: تم استلام مبلغ | E5: البيان | F5: مطلوب مبلغ | G5: البيان
A6: 1 | B6: 1 | C6: 46073 | D6: 75 | F6: 75 | G6: تحت حساب صيانة شهر يناير/2026
A7: 2 | B7: 2 | C7: 46073 | D7: 75 | F7: 75 | G7: تحت حساب صيانة شهر فبراير/2026
A8: 3 | B8: 3 | C8: 46122 | D8: 75 | F8: 75 | G8: تحت حساب صيانة شهر مارس /2026
A9: 4 | B9: 4 | C9: 46116 | D9: 75 | F9: 75 | G9: تحت حساب صيانة شهر ابريل /2026
A10: 5 | B10: 5 | C10: 46144 | D10: 75 | F10: 75 | G10: تحت حساب صيانة شهر مايو /2026
A11: 6 | B11: 6 | C11: 46176 | D11: 150 | F11: 150 | G11: تحت حساب صيانة شهر يونية /2026
A12: 7 | B12: 7 | C12: 46204 | D12: 150 | F12: 150 | G12: تحت حساب صيانة شهر يولية /2026
A13: 8 | B13: 8 | C13: 46237 | D13: 150 | F13: 150 | G13: تحت حساب صيانة شهر اغسطس /2026
A14: 9 | B14: 9 | C14: 46299 | D14: 150 | F14: 150 | G14: تحت حساب صيانة شهر سبتمبر /2026
A15: 10 | B15: 10 | C15: 46299 | D15: 150 | F15: 150 | G15: تحت حساب صيانة شهر اكتوبر /2026
A16: 11 | B16: 11 | C16: 46350 | D16: 150 | F16: 150 | G16: تحت حساب صيانة شهر نوفمبر /2026
A17: 12 | B17: 12 | C17: 46350 | D17: 150 | F17: 150 | G17: تحت حساب صيانة شهر ديسمبر /2026

Sheet Apartment1
C2: صفحة شقة رقم 1 - عمرو نبيل
D3: إجمالى الايرادات | F3: إجمالى المبلغ المطلوب
D4: =SUM(D6:D2001) -> 1050 | F4: =SUM(F6:F2001) -> 1800 | M4: خالص
A5: م | B5: شهر | C5: بتاريخ | D5: تم استلام مبلغ | E5: البيان | F5: مطلوب مبلغ | G5: البيان
A6: 1 | B6: 1 | C6: 46034 | D6: 150 | F6: 150 | G6: تحت حساب صيانة شهر يناير/2026
A7: 2 | B7: 2 | C7: 46087 | D7: 150 | F7: 150 | G7: تحت حساب صيانة شهر فبراير/2026
A8: 3 | B8: 3 | C8: 46115 | D8: 150 | F8: 150 | G8: تحت حساب صيانة شهر مارس /2026
A9: 4 | B9: 4 | C9: 46222 | D9: 150 | F9: 150 | G9: تحت حساب صيانة شهر ابريل /2026
A10: 5 | B10: 5 | C10: 46222 | D10: 150 | F10: 150 | G10: تحت حساب صيانة شهر مايو /2026
A11: 6 | B11: 6 | C11: 46232 | D11: 150 | F11: 150 | G11: تحت حساب صيانة شهر يونية /2026
A12: 7 | B12: 7 | C12: 46232 | D12: 150 | F12: 150 | G12: تحت حساب صيانة شهر يولية /2026
A13: 8 | B13: 8 | C13: 46306 | F13: 150 | G13: تحت حساب صيانة شهر اغسطس /2026
A14: 9 | B14: 9 | C14: 46306 | F14: 150 | G14: تحت حساب صيانة شهر سبتمبر /2026
A15: 10 | B15: 10 | C15: 46360 | F15: 150 | G15: تحت حساب صيانة شهر اكتوبر /2026
A16: 11 | B16: 11 | C16: 46360 | F16: 150 | G16: تحت حساب صيانة شهر نوفمبر /2026
A17: 12 | B17: 12 | C17: 46360 | F17: 150 | G17: تحت حساب صيانة شهر ديسمبر /2026

Sheet incomes
A2: Column1 | B2: Column2 | C2: Column3 | D2: Column4 | E2: Column5 | F2: Column6 | G2: Column7 | H2: Column8 | I2: Column9 | J2: Column10 | K2: Column11 | L2: Column12 | M2: Column13 | N2: Column14 | O2: Column15 | P2: Column16 | Q2: Column17
B3: صفحة الإيرادات
B4: إجمالى الايرادات: | C4: =SUM(C6:C2000) -> 19731
A5: م | B5: بتاريخ | C5: تم استلام مبلغ | D5: كود المالك | E5: اسم المالك | F5: لشقة رقم | G5: البيان
A6: 1 | B6: 46009 | C6: 0 | E6: حاج/ حسين | F6: 10 | G6: تحت حساب صيانة سنة 2025 بالكامل وسنة 2026، 2027 بالكامل بوقع 450 جنيه للشقتين، بمعنى 150جنيه لشقة 10 الغير مشغولة و 300جنيه لشقة 6 المشغولةـ، ملحوظة: لم يتم وضع مبلغ فى خانة استلام المبلغ لانه تم اثباته سنه 2025
A7: 2 | B7: 46022 | C7: 75 | E7: سلمى | F7: 2 | G7: تحت حساب صيانة شهر يناير /2026
A8: 3 | B8: 46024 | C8: 300 | E8: وائل محمد على | F8: 7 | G8: تحت حساب صيانة شهر يناير /2026
A9: 4 | B9: 46024 | C9: 150 | E9: د.عمرو | F9: 4 | G9: تحت حساب صيانة شهر يناير /2026
A10: 5 | B10: 46024 | C10: 150 | E10: م/نادية | F10: 3 | G10: تحت حساب صيانة شهر يناير /2026
A11: 6 | B11: 46026 | C11: 250 | E11: ا/عبد المجيد | F11: 12 | G11: تحت حساب صيانة شهر يناير /2026
A12: 7 | B12: 46037 | C12: 150 | E12: م/آمال | F12: 1 | G12: تحت حساب صيانة شهر يناير/2026
A13: 8 | B13: 46023 | C13: 300 | E13: وائل محمد على | F13: 7 | G13: تحت حساب صيانة شهر فبراير /2026
A14: 9 | B14: 46023 | C14: 150 | E14: د.عمرو | F14: 4 | G14: تحت حساب صيانة شهر فبراير /2026
A15: 10 | B15: 46023 | C15: 150 | E15: م/نادية | F15: 3 | G15: تحت حساب صيانة شهر فبراير /2026
A16: 11 | B16: 46023 | C16: 300 | E16: أ/مصطفى | F16: 8 | G16: تحت حساب صيانة شهر يناير /2026
A17: 12 | B17: 46065 | C17: 250 | E17: ا/عبد المجيد | F17: 12 | G17: تحت حساب صيانة شهر فبراير /2026
... A25: 20 | B25: 46085 | C25: 900 | E25: ا/سامى | F25: 5 | G25: تحت حساب صيانة شهور يناير وفبراير ومارس / 2026
A26: 21 | B26: 46044 | C26: 58 | E26: البنك الاهلى | G26: تحت حساب فوائد شهادة رقم 1807951149146700023 بتاريخ اصدار 21- ديسمبر - 2025 بفائدة 14%، عن شهر يناير/ 2026
A27: 22 | B27: 46075 | C27: 58 | E27: البنك الاهلى | G27: تحت حساب فوائد شهادة رقم 1807951149146700023 بتاريخ اصدار 21- ديسمبر - 2025 بفائدة 14%، عن شهر فبراير / 2026
A28: 23 | B28: 46092 | C28: 300 | E28: وائل محمد على | F28: 7 | G28: تحت حساب صيانة شهر ابريل /2026
A29: 24 | B29: 46092 | C29: 150 | E29: د.عمرو | F29: 4 | G29: تحت حساب صيانة شهر ابريل /2026
A30: 25 | B30: 46092 | C30: 150 | E30: م/نادية | F30: 3 | G30: تحت حساب صيانة شهر ابريل /2026
A31: 26 | B31: 46092 | C31: 450 | E31: ايمان | F31: 11 | G31: تحت حساب صيانة شهور يناير وفبراير ومارس / 2026
A32: 27 | B32: 46092 | C32: 450 | E32: سعد عنان | F32: 9 | G32: تحت حساب صيانة شهور يناير وفبراير ومارس / 2026
A33: 28 | B33: 46093 | C33: 300 | E33: أ/مصطفى | F33: 8 | G33: تحت حساب صيانة شهر مارس /2026
A34: 29 | B34: 46097 | C34: 750 | E34: منال | F34: 13، 14 | G34: تحت حساب صيانة شهور يناير وفبراير ومارس / 2026
A35: 30 | B35: 46116 | C35: 75 | E35: سلمى | F35: 2 | G35: تحت حساب صيانة شهر ابريل /2026
A36: 31 | B36: 46115 | C36: 150 | E36: م/آمال | F36: 1 | G36: تحت حساب صيانة شهر مارس /2026
A37: 32 | B37: 46103 | C37: 58 | E37: البنك الاهلى | G37: تحت حساب فوائد شهادة رقم 1807951149146700023 بتاريخ اصدار 21- ديسمبر - 2025 بفائدة 14%، عن شهر مارس / 2026
A38: 33 | B38: 46117 | C38: 246 | E38: البنك الاهلى | G38: تحت حساب فوائد شهادة رقم 1807581149146700038 بتاريخ اصدار 4- يناير - 2026 بفائدة 19.25%، عن شهر ابريل / 2026
A39: 34 | B39: 46115 | C39: 250 | E39: ا/عبد المجيد | F39: 12 | G39: تحت حساب صيانة شهر مارس /2026
A40: 35 | B40: 46142 | C40: 300 | E40: وائل محمد على | F40: 7 | G40: تحت حساب صيانة شهر مايو /2026
A41: 36 | B41: 46142 | C41: 150 | E41: د.عمرو | F41: 4 | G41: تحت حساب صيانة شهر مايو /2026
A42: 37 | B42: 46142 | C42: 150 | E42: م/نادية | F42: 3 | G42: تحت حساب صيانة شهر مايو /2026
A43: 38 | B43: 46134 | C43: 58 | E43: البنك الاهلى | G43: تحت حساب فوائد شهادة رقم 1807951149146700023 بتاريخ اصدار 21- ديسمبر - 2025 بفائدة 14%، عن شهر ابريل / 2026
A44: 39 | B44: 46144 | C44: 75 | E44: سلمى | F44: 2 | G44: تحت حساب صيانة شهر مايو /2026
A45: 40 | B45: 46149 | C45: 600 | E45: ا/سامى | F45: 5 | G45: تحت حساب صيانة شهور ابريل ومايو / 2026
A46: 41 | B46: 46152 | C46: 500 | E46: ا/عبد المجيد | F46: 12 | G46: تحت حساب صيانة شهر ابريل و مايو /2026
A47: 42 | B47: 46158 | C47: 600 | E47: أ/مصطفى | F47: 8 | G47: تحت حساب صيانة شهر ابريل ومايو /2026
A48: 43 | B48: 46158 | C48: 450 | E48: سعد عنان | F48: 9 | G48: تحت حساب صيانة شهور ابريل و مايو ويونية / 2026
...

Sheet balance
B2: صفحة الرصيد
B3: رصيد مرحل 2026 | C3: 13902
A4: م | C4: إجمالى الايرادات | D4: إجمالى المصروفات | E4: الرصيد
A5: 1 | C5: =incomes!C4 -> 19731 | D5: =outcomes!C3 -> 22921 | E5: =(C3+C5)-D5 -> 10712

Sheet outcomes
B2: صفحة المصروفات
B3: إجمالى المصروفات: | C3: =SUM(C5:C2002) -> 22921
A4: م | B4: بتاريخ | C4: تم دفـــع مبلغ | D4: البيان | S4: كود
A5: 1 | B5: 46023 | C5: 100 | D5: تحت حساب اصلاح كالون باب الخشب الرئيسى للعمارة وتريحه بحيث يقفل ويفتح الكالون من بره بسهولة | S5: 4
A6: 2 | B6: 46035 | C6: 1100 | D6: تحت حساب اصلاح الموتور - تغيير الرولمان بيلى و الاولسيه بالخراط ب 750جنيه و مصنعية 300جنيه و 50جنيه لاحمد السباك الشاب | S6: 3
A7: 3 | B7: 46039 | C7: 50 | D7: تحت حساب صيانة وتسليك المجارى بالجراج | S7: 1
A8: 4 | B8: 46046 | C8: 1023 | D8: تحت حساب كهرباء شهر يناير /2026 | S8: 1
A9: 5 | B9: 46058 | C9: 400 | D9: تحت حساب نظافة السلم لام احمد عن شهر يناير /2026 | S9: 2
A10: 6 | B10: 46058 | C10: 50 | D10: تحت حساب شراء لزوم نظافة العمارة والمسح بايريال و كلوريكس | S10: 6
A11: 7 | B11: 46058 | C11: 50 | D11: تحت حساب تسليك المجارى لعامل المجارى | S11: 1
A12: 8 | B12: 46067 | C12: 930 | D12: تحت حساب فاتورة المياه عن شهر يناير /2026 | S12: 1
A13: 9 | B13: 46067 | C13: 930 | D13: تحت حساب فاتورة المياه عن شهر فبراير /2026 | S13: 4
A14: 10 | B14: 46075 | C14: 683 | D14: تحت حساب كهرباء شهر فبراير /2026 | S14: 1
A15: 11 | B15: 46075 | C15: 3 | D15: تحت حساب اكرامية للمحصل | S15: 6
A16: 12 | B16: 46075 | C16: 20 | D16: تحت حساب كهربة خلفية المنزل | S16: 6
... A24: 20 | B24: 46126 | C24: 1030 | D24: تحت حساب فاتورة المياه عن شهر ابريل /2026 | S24: 1
A25: 21 | B25: 46129 | C25: 285 | D25: تحت حساب كهرباء شهر ابريل /2026
A26: 22 | B26: 46129 | C26: 5 | D26: اكرامية لمحصل الكهرباء
A27: 23 | B27: 46142 | C27: 400 | D27: تحت حساب نظافة السلم لام احمد عن شهر ابريل /2026 | S27: 6
A28: 24 | B28: 46142 | C28: 50 | D28: تحت حساب شراء كيس ايريال
A29: 25 | B29: 46155 | C29: 1030 | D29: تحت حساب فاتورة المياه عن شهر مايو /2026
A30: 26 | B30: 46158 | C30: 463 | D30: تحت حساب كهرباء شهر مايو /2026
A31: 27 | B31: 46159 | C31: 1000 | D31: تحت حساب اصلاح الموتور - شراء شيك بلف 575 ج - لاكور وكتان وحاجة ثانية وتفلون 110 ج - ومصنعية 315 ج
A32: 28 | B32: 46168 | C32: 400 | D32: تحت حساب نظافة السلم لام احمد عن شهر مايو /2026
A33: 29 | B33: 46189 | C33: 238 | D33: تحت حساب كهرباء شهر يونيه /2026 | T33: تسوية
A34: 30 | B34: 46189 | C34: 5 | D34: اكرامية لمحصل الكهرباء
A35: 31 | B35: 46197 | C35: 1030 | D35: تحت حساب فاتورة المياه عن شهر يونيه /2026
A36: 32 | B36: 46197 | C36: 400 | D36: تحت حساب نظافة السلم لام احمد عن شهر يونيه /2026
A37: 33 | B37: 46217 | C37: 20 | D37: تحت حساب نظافة امام العمارة
A38: 34 | B38: 46220 | C38: 231 | D38: تحت حساب كهرباء شهر يوليه /2026
A39: 35 | B39: 46225 | C39: 1030 | D39: تحت حساب فاتورة المياه عن شهر يوليه /2026
A40: 36 | B40: 46234 | C40: 400 | D40: تحت حساب نظافة السلم لام احمد عن شهر يولية /2026
A41: 37 | B41: 46234 | C41: 50 | D41: تحت حساب شراء كيس ايريال
A42: 38 | B42: 46254 | C42: 1030 | D42: تحت حساب فاتورة المياه عن شهر اغسطس /2026
A43: 39 | B43: 46262 | C43: 400 | D43: تحت حساب نظافة السلم لام احمد عن شهر اغسطس /2026
A44: 40 | B44: 46264 | C44: 243 | D44: تحت حساب كهرباء شهر اغسطس /2026
A45: 41 | B45: 46264 | C45: 2 | D45: اكرامية لمحصل الكهرباء
... A52: 48 | B52: 46316 | C52: 875 | D52: تحت حساب فاتورة المياه عن شهر سبتمبر /2026
A53: 49
A54: 50
...

Sheet op_codes
A1: كود
A2: 1 | B2: كهرباء
A3: 2 | B3: مياه
A4: 3 | B4: موتور
A5: 4 | B5: الصرف
A6: 5 | B6: طوارئ
A7: 6 | B7: نظافة السلم
A8: 7 | B8: نور السلم
A9: 8 | B9: تسوية

Sheet Sheet1
I6: مدين | J6: دائن
H7: ايمان | I7: 1200
H8: كهرباء | J8: 1434
H9: رسوم | J9: 18
H11: اجمالى | I11: =SUM(I7:I10) -> 1200 | J11: =SUM(J7:J10) -> 1452
H12: رصيد | K12: =J11-I11 -> 252
